Workbook

Sheet IEEE - Tabulação de resultados
A1: Author full names | B1: Author(s) ID | F1: Title | G1: Year | H1: Abstract | I1: Authors | J1: Volume | K1: Issue | L1: Art. No. | M1: Page start | N1: Page end | O1: Page count | P1: Cited by | Q1: DOI | R1: Link | S1: References | T1: Document Type | U1: Open Access | V1: Source | W1: EID
A2: Horigian, Viviana E. (14019795400); Perrino, Tatiana (6603459077); Kornfeld, Julie (8957646800); Schmidt, Renae D. (57219426983); Gonzalez, Sophia T. (57961624400) | B2: 14019795400; 6603459077; 8957646800; 57219426983; 57961624400 | C2: Inconforme - Publicações indisponíveis para download ou visualização | D2: Inconforme - Publicações indisponíveis para download ou visualização | F2: 3 The Repercussions of Teaching in the Digital Era: A Boon or Bane? LIVRO | G2: 2024 | H2: This book comprehensively covers the evolution of advanced learning pedagogy and innovative technologies like open educational resources and blended learning models. It specifically talks about the future of technology-enhanced learning and how advanced technology and government policies together are trying to impact learning outcomes globally. Nowadays in a flexible learning environment, technology plays a significant role in higher education systems. Both educators and students are playing prominent roles in its successful implementation. Advanced learning pedagogy by using technology has not only changed teaching procedures but has also evolved the relationship among multiple stakeholders. The content of the book is neatly segregated into four parts. Part I covers the concept and evolution of digital learning and education technology. This part examines the role of technology in higher education and proposes a toolkit for personalized learning and continuous assessment. Parts II and III creatively represent the innovative teaching techniques and learning models under advance learning pedagogy. Chapters under parts II and III are specially designed to present the more simplistic view of various technology-based advanced learning models and resources like flipped classes, gaming designs for e-learning, etc. Part III of the book also extensively covers various case studies/instructor’s stories of technology enabled learning experiences. Part IV focuses on the evaluation of advance learning pedagogy and tools. It also covers the future of information in learning (like formative analytics) and improved learning outcomes using technology and government initiatives in the form of various future oriented education policies like the Digital Action Education Plan (2021–2027). The wide-ranging content also covers the challenges of implementation of advanced learning pedagogy and offers recommendations to overcome such challenges. The book will grab the attention of the modern (IT-enabled) instructor’s fraternity, and students and researchers in the area of technology and education. The book can be further used by policymakers and educational-technology startups to formulate and design technology-based higher education teaching policies and procedures which are indeed helpful in measuring learning outcomes. | I2: Pallavi Tyagi; Ranjan Shruti; R. K. Gola | J2: 12 | M2: 33 | N2: 46 | O2: 13 | P2: 2 | Q2: 10.1109/ACCESS.2024.3393769 | R2: https://ieeexplore.ieee.org/document/10348131 | T2: fechado | U2: livre
A3: Claybrook, M. Keith (57222062335) | B3: 57222062335 | C3: Inconforme - Não está conforme o tema | D3: Inconforme - Não está conforme o tema | F3: A Multigranularity Learning Path Recommendation Framework Based on Knowledge Graph and Improved Ant Colony Optimization Algorithm for E-Learning | G3: 2024 | H3: In e-learning, extracting suitable learning objects (LOs) from a vast resource pool and organizing them into high-quality learning paths is crucial for helping e-learners achieve their goals. Numerous approaches have been proposed to recommend optimal learning paths for e-learners. However, it is essential to emphasize that e-learning systems typically consist of a wide range of LOs with varying levels of granularity, ranging from fine-grained to coarse-grained. Unfortunately, current research has not adequately considered the underlying granularity structure of LOs when optimizing learning paths. Existing methods primarily focus on organizing LOs at a single granularity level, limiting their applicability in real-world e-learning systems. To address the limitations, we propose a multigranularity learning path recommendation (MGLPR) framework that aims to flexibly and effectively integrate the diverse granularity levels of LOs into high-quality learning paths. In this framework, a two-layer [knowledge point (KP) and LO layers] model is developed to formulate the MGLPR problem as a constrained optimization problem and an improved ant colony optimization algorithm (IACO) is introduced to solve it to identify optimal learning paths for e-learners. To evaluate the effectiveness of the proposed IACO, we conducted extensive computational experiments using 30 simulation datasets with varying problem sizes and complexities. The results demonstrate that our proposed IACO achieves superior performance and robustness compared with other competitors. Additionally, an empirical study was conducted to investigate the efficacy of the proposed approach in an authentic learning context, with results indicating that the proposed method outperforms the traditional self-organized ones. | I3: Yaqian Zheng; Deliang Wang; Yaping Xu; Yanyan Li All Authors | J3: 12 | K3: 2 | M3: 586 | N3: 607 | O3: 21 | P3: 3 | Q3: 10.1109/TCSS.2024.3488373 | R3: https://ieeexplore.ieee.org/document/10750152 | T3: artigo | U3: livre
A4: Kuo, Yu-Chen (56323018000) | B4: 56323018000 | C4: Inconforme - Publicações com menos ou igual a 4 páginas | F4: An Analysis of Gamified Mobile Applications to Educate Children about Astronomy | G4: 2022 | H4: Teaching astronomy to children has the potential to develop their imagination and critical thinking and might encourage them to pursue a career in science, technology, engineering, and mathematics (STEM) related fields. Gamified mobile applications are tools that could be used to teach effectively astronomy concepts to children by simplifying them and making the learning experience fun and engaging. This study analyzed and assessed the specifications of 6 gamification-based applications for astronomy education, covering their content and technical features. The scoring system assigned a score with a rating from very high to very low for each of the applications. None of the applications scored a very high rating, in either the content or the technical features. The technical features have an overall lower score relative to the content. We discussed the implications of our findings in the paper and suggested recommendations for the developers of future astronomy-related applications. | I4: Eslam Ahmed; Rim Fares; Ali Ibrahim; Sofia Ouhbi | M4: 532 | N4: 536 | O4: 4 | P4: 1 | Q4: 10.1109/EDUCON52537.2022.9766712 | R4: https://ieeexplore.ieee.org/document/9766712 | T4: conferencia | U4: livre | V4: 2022 IEEE Global Engineering Education Conference (EDUCON)
A5: Montfort, Devlin (23094812600); Ideker, Jason H. (15834405300); Parham-Mocello, Jennifer (57208305812); Skilowitz, Rowan Ezra (58616124600); Mallette, Natasha (58578753900) | B5: 23094812600; 15834405300; 57208305812; 58616124600; 58578753900 | C5: Inconforme - Não está conforme o tema | D5: Inconforme - Não está conforme o tema | F5: Analyzing Investor Behavior Shifts Under AI Influence: A Deep Learning Perspective | G5: 2025 | H5: This study investigates the behavioral impacts of artificial intelligence (AI) on the investment decision-making patterns of Indian investors, with a focus on AI-driven tools such as stock market chatbots, robo-advisors, and sentiment-based trading bots. The research framework employs multiple deep learning architectures to capture and analyze different dimensions of investor behavior. Deep Neural Networks (DNN) are utilized for classification to determine whether exposure to AI influences portfolio allocation towards higher-risk assets. Long Short-Term Memory (LSTM) networks are applied to model time-dependent changes in risky asset allocation, while Deep Factorization Machines (DeepFM) are used to rank investors by their likelihood of following AI-generated recommendations without verification. Additionally, transformer-based models like BERT process investor communications from platforms such as WhatsApp, Telegram, and online forums to extract sentiment features. Data preprocessing includes Min-Max normalization, median-based imputation, sliding-window segmentation for time-series analysis, and sentiment integration. Decision thresholds—0.75 for DNN classification, +5% allocation change for LSTM regression, and top 30% ranking cutoff for DeepFM—are implemented to balance predictive accuracy with responsible financial guidance. A T-learner framework is incorporated for causal inference, isolating the behavioral effect attributable specifically to AI exposure. The evaluation employs precision, recall, ROC-AUC, RMSE, MAE, NDCG, and SHAP-based explainability measures. The system is deployed on cloud infrastructure with real-time monitoring to ensure stability, interpretability, and regulatory compliance. Findings aim to inform policy, enhance investor education, and ensure ethical AI integration in India’s financial sector while safeguarding against potential risks of overreliance on AI-generated investment advice. | I5: S. Pravin; S Jegadeesan; R. Santhana Krishnan; M. Saravana Karthikeyan; J. Relin Francis Raj; M. Arun Kumar | M5: 1661 | N5: 1668 | O5: 7 | P5: 33 | Q5: 10.1109/ICIDCA66325.2025.11280472 | R5: https://ieeexplore.ieee.org/document/11280472 | T5: Conferencia | U5: livre | V5: 7th International Conference on Innovative Data Communication Technologies and Application (ICIDCA)
A6: Lange, Christopher (57189341479); Gorbunova, Anna (57481924000); Shcheglova, Irina (57204425215); Costley, Jamie (56771275500) | B6: 57189341479; 57481924000; 57204425215; 56771275500 | C6: Inconforme - Publicações com menos ou igual a 4 páginas | F6: Analyzing Key LinkedIn Profile Factors for Securing Employment with Leading Roles | G6: 2025 | H6: Professional social media is widely used by the population seeking to market themselves to potential employers. As the job market becomes ever more increasingly competitive, the need to have an exceptional profile to stand out grows as well. The significance of having an attractive profile on professional social media, such as LinkedIn, thus cannot be ignored in influencing the decision to get a high-level job position. This study employs machine learning models, including Logistic Regression, Random Forest, and DistillBERT, along with SHAP explainability to analyze LinkedIn profile features most predictive of high-level employment. Results indicate that Logistic Regression performs best, with number of recommendations and interests ranking highest in importance. Surprisingly, follower count had mini-mal influence. These insights can directly inform recruitment strategies, such as tailoring algorithms for candidate shortlisting, and profile optimization tools that guide users in enhancing key features. Future work may expand dataset diversity and explore real-time profile evaluation systems based on these insights. | I6: K. E. Tjandra, B. G. Tunjung, H. Lucky and D. Suhartono | M6: 380 | N6: 384 | O6: 4 | P6: 30 | Q6: 10.1109/AiDAS67696.2025.11213607 | R6: https://ieeexplore.ieee.org/document/11213607 | T6: conferencia | U6: livre | V6: 2025 6th International Conference on Artificial Intelligence and Data Sciences (AiDAS)
A7: Riera, Fernando (58752509000); Estrada, Diana (58752738600); Guerrero, Solange E. (58487403000); Pacheco, Edwin (58753200800); Guevara, Sofía (58752738700); Arreaga, Raúl (58752738800) | B7: 58752509000; 58752738600; 58487403000; 58753200800; 58752738700; 58752738800 | C7: Inconforme - Não está conforme o tema | D7: Inconforme - Não está conforme o tema | F7: A Matching Platform for Academic Collaboration of Computer Science Students Through Natural Language Processing | G7: 2025 | H7: Ever since the recent years, social and entertainment application have been an essential part of our life where it helps the user to find friends or gives recommendations. Tinder and TikTok are notable examples, offering precise suggestions based on interests and behavioral data: Tinder provides users with people they, in essence, might find compatible with themselves based on people's answers and likes, whereas TikTok presents people with the content they may find interesting. In this research we deploy natural language processing based recommendation hybrid systems. NLP improves mining of behavioral patterns as it is possible to discover applicant's scholarly interests and choices from text descriptions of profiles which helps to have a better understanding of users' requirements. For users with similar academic backgrounds and interests, we conduct collaborative filtering, for topics of interest we use content based filtering while for a higher accuracy, we combine both techniques. Clustering categorizes students based on their goals, whereas, reinforcement learning modifies the recommendations depending on the student response. Opinion analysis results prove that the integrated use of the profile analysis based on NLP tools, as well as interest-based and content recommendation algorithms enhances match accuracy and users' engagement. This research provides a starting point for subsequent uses of educational technologies, improving academic cooperation, learning effectiveness, and individualized education. | I7: Qin Wei Xiong; Noor Hasrina Binti Bakar; Siti Zainab Binti Ibrahim; Danish Javed; Mohsen Marjani | M7: 639 | N7: 646 | O7: 7 | P7: 5 | Q7: 10.1109/ETNCC66224.2025.11299711. | R7: https://ieeexplore.ieee.org/document/11299711 | T7: conferencia | U7: livre | V7: 2025 International Conference on Emerging Trends in Networks and Computer Communications (ETNCC)
A8: Wang, Yi-Ping (57192838872) | B8: 57192838872 | C8: Inconforme - Estudos que já são RSL/MS (Estudos secundários) | F8: Big Educational Data & Analytics: Survey, Architecture and Challenges | G8: 2020 | H8: The proliferation of mobile devices and the rapid development of information and communication technologies (ICT) have seen increasingly large volume and variety of data being generated at an unprecedented pace. Big data have started to demonstrate significant values in higher education. This paper gives several contributions to the state-of-the-art for Big data in higher education and learning technologies research. Currently, there is no comprehensive survey or literature review for Big educational data. Most literature reviews from a few authors have focused on one of these fields: educational mining, learning analytics with discussions on one or two aspects such as Big data technologies without educational focus, social media data in education, etc. Most of these literature reviews are short and insufficient to provide more inclusive reviews for Big educational data. In this paper, we present a comprehensive literature review of the current and emerging paradigms for Big educational data. The survey is presented in five parts: (1) The first part presents an overview and classification of Big education research to show the full landscape in this field, which also gives a concise summary of the overall scope of this paper; (2) The second part presents a discussion for the various data sources from education platforms or systems including learning management systems (LMS), massive open online courses (MOOC), learning object repository (LOR), OpenCourseWare (OCW), open educational resources (OER), social media, linked data and mobile learning contributing to Big education data; (3) The third part presents the data collection, data mining and databases in Big education data; (4) The fourth part presents the technological aspects including Big data platforms and architectures such as Hadoop, Spark, Samza and Big data tools for Big education data; and (5) The fifth part presents different approaches of data analytics for Big education data. This part provides a more inclusive discussion on data analytics which is beyond traditional forms of learning analysis in higher education. This includes predictive analytics, learning analytics including collaborative, behavior, personal learnings and assessment, followed by recommendation systems, graph analytics, visual analytics, immersive learning and analytics, etc. The final part of the paper discusses social (e.g. privacy and ethical issues) and technological challenges for Big data in education. This part also illustrates the technological challenges faced by giving an example for utilizing graph-based analytics for a cross-institution learning analytics scenario. | I8: Kenneth Li-Minn Ang; Feng Lu Ge; Kah Phooi Seng | J8: 8 | M8: 116392 | N8: 116414 | O8: 22 | P8: 108 | Q8: 10.1109/ACCESS.2020.2994561 | R8: https://ieeexplore.ieee.org/document/9093868 | T8: artigo | U8: livre | V8: IEEE Access
A9: Han, Xiuqin (57289063900); Xing, Xiaohui (57976629400); Gao, Chen (57976629500); Yang, Hongliang (56330437100); Pan, Xudong (24073631300); Lei, Chengxi (35795508400) | B9: 57289063900; 57976629400; 57976629500; 56330437100; 24073631300; 35795508400 | C9: Inconforme - Não está conforme o tema | D9: Inconforme - Não está conforme o tema | F9: CIPPO: Contrastive Imitation Proximal Policy Optimization for Recommendation Based on Reinforcement Learning | G9: 2024 | H9: Recommendation systems, widely adopted in social networks, personalize user experiences through advanced technologies such as Reinforcement Learning (RL), known for producing high-performance, list-wise recommendations. However, RL-based recommendation methods exhibit biases, specifically: 1) Online bias, which stems from a complex real-world online policy composed of various rules and models rather than a single policy; 2) Training bias, a distributional shift resulting from differences between the target policy and the behavior policy. To address these issues, we introduce a novel framework named Contrastive Imitation Proximal Policy Optimization (CIPPO) for recommendation based on RL. This approach leverages extensively labeled feedback data and incorporates a Masked Imitation Network (MIN) that closely emulates the online policy, thus reducing discrepancies between online and offline environments. Additionally, the clipping function in Proximal Policy Optimization, combined with a specially designed contrastive module, effectively reduces the distributional shift between the behavior and target policies. We conduct offline and online experiments to show the improvements of CIPPO, providing details including ablation tests and parameter analysis to validate the effectiveness and robustness. CIPPO gains 12.79% on ACN and in WeChat Top Stories, a large media platform with over 50 million users. | I9: Weilong Chen; Shaoliang Zhang; Ruobing Xie; Feng Xia; Leyu Lin; Xinran Zhang | J9: 36 | M9: 5753 | N9: 5767 | O9: 14 | P9: 2 | Q9: 10.1109/TKDE.2024.3402649 | R9: https://ieeexplore.ieee.org/document/10534824 | T9: artigo | U9: livre | V9: IEEE Transactions on Knowledge and Data Engineering
A10: Setambah, Mohd Afifi Bahurudin (57208423455); Tajudin, Nor'ain Mohd (57204495196); Yaakob, Mohd Faiz Mohd (57203537360); Saad, Muhamad Ikhwan Mat (57209616516) | B10: 57208423455; 57204495196; 57203537360; 57209616516 | C10: Inconforme - Não está conforme o tema | D10: Inconforme - Não está conforme o tema | F10: Dynamic Graph Learning to Denoise Implicit Feedback for Graph Collaborative Filtering | G10: 2025 | H10: Due to the inherent challenges in acquiring explicit feedback, graph collaborative filtering (GCF) models often resort to implicit feedback. However, there exists noise in implicit feedback that may not accurately reflect users’ preferences. This noise will be amplified by the aggregating and propagating operations of GCF, thereby affecting the performance of GCF. Existing noise mitigation methods attempt to filter noisy samples from implicit feedback data, yet they face limitations such as dependency on side information for sample selection, neglect of false-negative noise, and disregard for the impact of previous selections on current iteration. To overcome these challenges, we propose a dynamic graph learning framework to denoise implicit feedback for GCF (DGLD). DGLD comprises a graph learning module and a reinforcement learning module. The graph learning module evaluates the confidence degrees of interactions by leveraging user–item cosine similarity and global user preferences, updating user–item interaction graph without relying on side information. Meanwhile, the reinforcement learning module employs a policy network to select “false-positive denoising” and “false-negative denoising” actions based on performance of the recommendation model and state of interaction graph obtained from previous iterations. These modules work synergistically to dynamically denoise implicit feedback. Experimental results on three benchmark datasets underscore the superiority of our approach over state-of-the-art general and denoising recommendation models. | I10: Huiting Liu; Xinchen Xiong; Peipei Li; Peng Zhao; Xindong Wu | J10: 12 | M10: 3947 | N10: 3959 | O10: 12 | P10: 1 | Q10: 10.1109/TCSS.2025.3564762 | R10: https://ieeexplore.ieee.org/document/11027132 | T10: artigo | U10: livre | V10: IEEE Transactions on Computational Social Systems
A11: Pongračić, Luka (57559114800); Marinac, Ana Maria (57557557100) | B11: 57559114800; 57557557100 | C11: Inconforme - Não está conforme o tema | D11: Inconforme - Não está conforme o tema | F11: Enhancing Social Recommendation With Adversarial Graph Convolutional Networks | G11: 2022 | H11: Social recommender systems are expected to improve recommendation quality by incorporating social information when there is little user-item interaction data. However, recent reports from industry show that social recommender systems consistently fail in practice. According to the negative findings, the failure is attributed to: (1) A majority of users only have a very limited number of neighbors in social networks and can hardly benefit from social relations; (2) Social relations are noisy but they are indiscriminately used; (3) Social relations are assumed to be universally applicable to multiple scenarios while they are actually multi-faceted and show heterogeneous strengths in different scenarios. Most existing social recommendation models only consider the homophily in social networks and neglect these drawbacks. In this paper we propose a deep adversarial framework based on graph convolutional networks (GCN) to address these problems. Concretely, for (1) and (2), a GCN-based autoencoder is developed to augment the relation data by encoding high-order and complex connectivity patterns, and meanwhile is optimized subject to the constraint of reconstructing the social profile to guarantee the validity of the identified neighborhood. After obtaining enough purified social relations for each user, a GCN-based attentive social recommendation module is designed to address (3) by capturing the heterogeneous strengths of social relations. Finally, we adopt adversarial training to unify all the components by playing a Minimax game and ensure a coordinated effort to enhance recommendation performance. Extensive experiments on multiple open datasets demonstrate the superiority of our framework and the ablation study confirms the importance and effectiveness of each component. | I11: Junliang Yu; Hongzhi Yin; Jundong Li; Min Gao; Zi Huang; Lizhen Cui | J11: 34 | M11: 3727 | N11: 3739 | O11: 12 | Q11: 10.1109/JCSSE58229.2023.10202102 | R11: https://ieeexplore.ieee.org/document/9239885 | T11: artigo | U11: Aberto | V11: IEEE Transactions on Knowledge and Data Engineering
A12: Kimberley, Anna (57204001961) | B12: 57204001961 | C12: Incoforme - Estudo duplicado | D12: Incoforme - Estudo duplicado | F12: Big Educational Data & Analytics: Survey, Architecture and Challenges | G12: 2020 | H12: The proliferation of mobile devices and the rapid development of information and communication technologies (ICT) have seen increasingly large volume and variety of data being generated at an unprecedented pace. Big data have started to demonstrate significant values in higher education. This paper gives several contributions to the state-of-the-art for Big data in higher education and learning technologies research. Currently, there is no comprehensive survey or literature review for Big educational data. Most literature reviews from a few authors have focused on one of these fields: educational mining, learning analytics with discussions on one or two aspects such as Big data technologies without educational focus, social media data in education, etc. Most of these literature reviews are short and insufficient to provide more inclusive reviews for Big educational data. In this paper, we present a comprehensive literature review of the current and emerging paradigms for Big educational data. The survey is presented in five parts: (1) The first part presents an overview and classification of Big education research to show the full landscape in this field, which also gives a concise summary of the overall scope of this paper; (2) The second part presents a discussion for the various data sources from education platforms or systems including learning management systems (LMS), massive open online courses (MOOC), learning object repository (LOR), OpenCourseWare (OCW), open educational resources (OER), social media, linked data and mobile learning contributing to Big education data; (3) The third part presents the data collection, data mining and databases in Big education data; (4) The fourth part presents the technological aspects including Big data platforms and architectures such as Hadoop, Spark, Samza and Big data tools for Big education data; and (5) The fifth part presents different approaches of data analytics for Big education data. This part provides a more inclusive discussion on data analytics which is beyond traditional forms of learning analysis in higher education. This includes predictive analytics, learning analytics including collaborative, behavior, personal learnings and assessment, followed by recommendation systems, graph analytics, visual analytics, immersive learning and analytics, etc. The final part of the paper discusses social (e.g. privacy and ethical issues) and technological challenges for Big data in education. This part also illustrates the technological challenges faced by giving an example for utilizing graph-based analytics for a cross-institution learning analytics scenario. | I12: Kenneth Li-Minn Ang; Feng Lu Ge; Kah Phooi Seng | J12: 8 | M12: 116392 | N12: 116414 | P12: 108 | Q12: 10.1109/ACCESS.2020.2994561 | R12: https://ieeexplore.ieee.org/document/9093868 | T12: artigo | U12: livre | V12: IEEE Access
A13: Kadar, Rozita (36608374200); Mahlan, Siti Balqis (57202914048); Shamsuddin, Maisurah (57220275240); Othman, Jamal (54384700500); Wahab, Naemah Abdul (57781783500) | B13: 36608374200; 57202914048; 57220275240; 54384700500; 57781783500 | C13: Inconforme - Publicações com menos ou igual a 4 páginas | F13: Enhancing Student Photography Skills with Web-based Photo Stock and Learning System | G13: 2023 | H13: Digital technology has greatly increased the use of photography as a visual communication tool in social media, advertising, and education. In parallel, photography education in higher education has become more important in providing students with the technical and creative skills they need to be successful in the field of photography. However traditional university digital photography teaching methods often resulting in low-quality student work and a lack of practical skills due to instructors at universities have different experiences and skills than professional photographers. In this research, we proposed the integration of a novel web-based photography recommendation system and Google Classroom learning system into our photography courses, thereby providing students hands-on high experience and real-world training. Our experimental results show that implementing our proposed method resulted in a significant increase in the average number of accepted photos in the order of 3.8 times previously achieved using traditional methods. As well, the number of students receiving an “A” grade increased by 2.8 times compared to the traditional teaching method. | I13: Thongsibsong et al. | M13: 454 | N13: 457 | O13: 4 | P13: 2 | R13: https://ieeexplore.ieee.org/document/10202102/ | T13: artigo | U13: livre | V13: 2023 20th International Joint Conference on Computer Science and Software Engineering (JCSSE)
A14: Yao, Jiannan (57681654500); Zhang, Xiuying (7410265589); Xue, Hui (15727089000); Zhu, Mingyue (57681378800); Wang, Jia (57358576800); Wang, Qiuchen (57235812900); Chen, Zhiming (57196282516); Yuan, Hua (57191828335) | B14: 57681654500; 7410265589; 15727089000; 57681378800; 57358576800; 57235812900; 57196282516; 57191828335 | C14: Inconforme - Não está conforme o tema | D14: Inconforme - Não está conforme o tema | F14: Evaluation of E- Learning in Engineering Education in Higher and Tertiary Education Institutions in Zimbabwe | G14: 2022 | H14: The adoption of ICTs and e-learning tools in institutions of higher education provides several benefits including enhancing engineering education. The Covid 19 global pandemic forced most institutions to adopt e-learning in order to improve access and quality of education. In order to evaluate the e-learning in higher and tertiary institutions, a cross sectional survey comprising of 32 instructors from the 5 departments in the faculty of engineering at Chinhoyi University of Technology (CUT) was carried out. Data collected using a survey questionnaire was analyzed using IBM SPSS Grad Pack version 28.0 premium. On average 23.34 % of the instructors never practiced e-learning, 18.96 % practiced e-learning rarely, 15.84 % practiced e-learning moderately, 12.48 %practiced e-learning substantially and 26.66 % practiced e-learning extensively in their teaching and learning. The usage of virtual laboratories and online assessment was found to be extremely low at 11.4 % respectively. The study revealed that CUT has an official e-learning strategy embedded in the ICT policy. About 63 % of the respondents were satisfied with the e-learning systems and affirmed that their productivity and performance improved through the use of the e-learning system. The existence of a sound e-learning policy has a direct impact on educational delivery. Although instructors had computers 88 % had no access to web cameras for online teaching and learning. The most prevalent challenge was power failure. The study recommended the development of e-learning quality assurance standards to ensure consistency and uniformity in the conveyance of e-learning in engineering education. The output of this will provide useful insights on the current usage of e-learning and recommendation to address the challenges affecting the adoption of ICTs and e-learning in higher and tertiary education institutions in Zimbabwe. | I14: Chihobo et al. | M14: 1 | N14: 5 | O14: 5 | Q14: 10.1109/WEEF-GEDC54384.2022.9996200 | R14: https://ieeexplore.ieee.org/document/9996200/ | T14: Conference Paper | U14: https://ieeexplore.ieee.org/document/9996200/ | V14: 2022 IEEE IFEES World Engineering Education Forum - Global Engineering Deans Council (WEEF-GEDC)
A15: Gevorkyan, Srbuhi R. (58812765200); Ispiryan, Mariam M. (57202759646); Sarkisyan, Vahan Zh. (58812351700); Tadevosyan, Hakob V. (58812903800) | B15: 58812765200; 57202759646; 58812351700; 58812903800 | C15: Inconforme - Publicações com menos ou igual a 4 páginas | F15: Formative e-assessment: An Evidence-based Recommendation for Engineering and Technology Courses in Bangladeshi Universities | G15: 2020 | H15: Formative assessment is an integral part of quality higher education where effective feedback helps students take ownership of learning, and strategise to reduce the gap between their existing state of learning and expected standards. Despite such benefits the uptake of formative assessment is limited in the context of technology courses at universities in Bangladesh. Considering accessibility potential and the reusability feature of assessment tasks in technology based solutions formative e-assessment is suggested in this conceptual paper for implementation in Bangladesh context. Recommendations are made for research based intervention and small-scale pilots before scaling up. | I15: Tanvir Ahmed; Faisal Tariq | M15: 1 | N15: 4 | O15: 4 | Q15: 10.1109/TREET50959.2020.9189754 | R15: https://ieeexplore.ieee.org/document/9189754/ | T15: Conferência | U15: https://ieeexplore.ieee.org/document/9189754/
A16: Qamar, Sayyad Zahid (7003995520); Arunachalam, Ramanathan (6602156310); Qamar, Sayyad Basim (57193113319) | B16: 7003995520; 6602156310; 57193113319 | C16: Inconforme - Não está conforme o tema | D16: Inconforme - Não está conforme o tema | F16: Hybrid Collaborative Recommendation Method via Dual-Autoencoder Framework for Analyzing Social Media Addiction and Student Behavior in Higher Education | G16: 2025 | H16: College students' opinions, engagement in a variety of activities, and even addictive behaviours are all impacted by the pervasiveness of social media use in their daily life. Many students view posts on substance use as funny or pleasant on social media sites like YouTube, Facebook, Myspace, and Twitter, according to previous study. These results highlight the impact of social media interactions on college students' actions. In order to discover more about this, they used the Shapiro-Wilk normality test, which verified that the data did not follow a normal distribution, to prepare and examine it. In order to find important behavioural traits, feature extraction techniques were used. To improve computational efficiency, they present HCRDa, a Hybrid Collaborative Recommendation method that uses a dual-autoencoder to learn feature representations of objects and users simultaneously. With a 98.31 % accuracy rate, the model clearly identified and predicted tendencies linked to social media addiction. Finally, the findings show that social media has an effect on college students' behaviour and that sophisticated computational models like HCRDa can help with monitoring and intervention programs to curb addiction. | I16: Kumar et. al. | M16: 1 | N16: 6 | O16: 6 | Q16: 10.1109/IACIS65746.2025.11211286 | R16: https://doi.org/10.1109/TREET50959.2020.9189754 | T16: Conference Paper | U16: https://ieeexplore.ieee.org/document/11211286/ | V16: 2025 2nd International Conference on Intelligent Algorithms for Computational Intelligence Systems (IACIS)
A17: Ogenrwot, Daniel (57219533681); Tabo, Geoffrey Olok (57219625311); Aber, Kevin (57819209900); Nakatumba-Nabende, Joyce (57197759951) | B17: 57219533681; 57219625311; 57819209900; 57197759951 | C17: Inconforme - Não está conforme o tema | D17: Inconforme - Não está conforme o tema | F17: Inhomogeneous Interest Modeling via Hypergraph Convolutional Networks for Social Recommendation | G17: 2024 | H17: To improve the performance of social recommendation, it can be beneficial to include social relationships, model user interests, and item attraction. Traditional methods use binary social relationships between users and items, known as ’user-user’ and ’user-item’, which rely on historical interactions like purchasing history and clickiing history equally. However, the interests and attractions aggregated by such approaches are incomplete. In addition to binary interactions, there are also a large number of ’user-item-user’ triple social behaviors, such as retweeting or recommending. Considering these triple social behaviors introduces inhomogeneity to the modeling of interests and attractions. Furthermore, beyond the primary explicit in-terest derived from interaction history, users are also influenced by secondary, latent interests in items shared by friends, which makes the modeling more complex. To address this issue, we propose IIMHGCN (Inhomogeneous Interest Modeling via Hy-pergraph Convolutional Networks). In addition to binary social relationships, we incorporate a hypergraph model that utilizes triple social recommendation behaviors and higher-order social connections to model inhomogeneous interests and attraction. We substantiate its effectiveness through extensive experiments on two real-world datasets. | I17: Luo et al. | M17: 1 | N17: 9 | O17: 9 | Q17: 10.1109/IJCNN60899.2024.10651102 | R17: https://ieeexplore.ieee.org/document/10651102/ | T17: Conference Paper | U17: https://ieeexplore.ieee.org/document/10651102/ | V17: 2024 International Joint Conference on Neural Networks (IJCNN) | W17: 2161-4407
A18: Lopes, Rui Pedro (35317655300); Mesquita, Cristina (56203897400); de la Cruz Del Río-Rama, María (56667582200); Álvarez-García, José (55623697400) | B18: 35317655300; 56203897400; 56667582200; 55623697400 | C18: Inconforme - Não está conforme o tema | D18: Inconforme - Não está conforme o tema | F18: Intelligent Decision System for Entrepreneurship Based on Big Data Analysis | G18: 2024 | H18: In the current field of entrepreneurship education, the lag and inefficiency of informatization and data-driven management are gradually becoming apparent. Therefore, this article adopts an intelligent decision system based on big data analysis to optimize the teaching mode and resource allocation of entrepreneurship education in universities. In response to the problem of insufficient data acquisition and analysis capabilities in the current teaching process, the system utilizes computer technology to integrate multiple data mining techniques and machine learning algorithms to achieve comprehensive perception and deep analysis of educational data. Firstly, an entrepreneurship education data perception network is built, integrating multiple data sources such as students' learning behaviors, teaching content, and social media feedback. Secondly, deep learning models such as convolutional neural networks and long short-term memory networks are used to extract learning feature signals at different scales. Then, based on methods such as decision tree algorithm, support vector machine, and random forest, a multimodal joint prediction model is established to achieve personalized learning path recommendation and educational effect prediction. In the dimension of "system performance", the proportions of 4 and 5 scores are relatively high, at 40.5% and 33.5% respectively, which further verifies the high evaluation of system performance by users. The studied intelligent decision system can significantly improve the teaching effectiveness and resource utilization of entrepreneurship education, effectively supporting education managers to make precise educational decisions and promoting the digital transformation and upgrading of entrepreneurship education in universities. | I18: Qi Ouyang | M18: 419 | N18: 425 | O18: 6 | Q18: 10.1109/ICEACE63551.2024.10898399 | R18: https://doi.org/10.1109/ICEACE63551.2024.10898399 | T18: Conferência | U18: https://ieeexplore.ieee.org/document/10898399/
A19: Pérez-Sánchez, Elkin O (36197125900); Chavarro-Miranda, Fernando (57219893048); Riano-Cruz, Julian D (57219895854) | B19: 36197125900; 57219893048; 57219895854 | C19: Inconforme - Publicações com menos ou igual a 4 páginas | F19: K-12 Teachers’Attitude Towards Online Learning Platfoms During COVID-19 Epidemic in China | G19: 2020 | H19: Cultural differences can impact how learning is delivered in higher education. Past studies have overlooked the impacts of specific cultures on learning and technology integration, and therefore, this article explores aspects of culture and resource implications for technology-enabled learning. The study collected data from students, lecturers, and university administrators at the University of Papua New Guinea via questionnaire (n = 58), focus group (n = 15), and interview (n = 2). Descriptive statistics of questionnaire responses supplemented by conventional content analysis of interview and focus group responses revealed perceptions of higher education and teaching in Papua New Guinea (PNG). Often, learning technologies are adopted without careful consideration of the users’ requirements, especially their cultural influences, which sometimes hinder the effective implementation of chosen technologies for learning. This article discusses the key findings related to technology limitations, cultural influences, communication issues, and other challenges unique to PNG. It highlights that students and lecturers are keen to embrace technology in teaching and learning; however, institutional constraints hinder the successful implementation of technology that would allow them to advance learning. This, coupled with cultural influences such as traditional customs, practices, and belief systems, also affects how Western education is delivered. The article concludes with recommendations for implementing culturally sensitive learning management systems that can accommodate infrastructure and social challenges. | I19: Peiyu Wang; Tianjiao Chen; Jie Liu; Heng Luo | M19: 19 | N19: 23 | O19: 4 | P19: 3 | Q19: 10.1109/EITT50754.2020.00010 | S19: https://ieeexplore.ieee.org/document/9320647 | T19: conferencia | U19: livre | V19: 2020 Ninth International Conference of Educational Innovation through Technology (EITT)
A20: Vargas-Murillo, Alfonso Renato (57711611300); de la Asuncion Pari-Bedoya, Ilda Nadia Monica (58478633800); de Jesús Guevara-Soto, Francisco (58537256000) | B20: 57711611300; 58478633800; 58537256000 | C20: Inconforme - Não está conforme o tema | D20: Inconforme - Não está conforme o tema | F20: Investigating Culture and Resource-Sensitive Technology-Enabled Learning | G20: 2025 | H20: Cultural differences can impact how learning is delivered in higher education. Past studies have overlooked the impacts of specific cultures on learning and technology integration, and therefore, this article explores aspects of culture and resource implications for technology-enabled learning. The study collected data from students, lecturers, and university administrators at the University of Papua New Guinea via questionnaire (n = 58), focus group (n = 15), and interview (n = 2). Descriptive statistics of questionnaire responses supplemented by conventional content analysis of interview and focus group responses revealed perceptions of higher education and teaching in Papua New Guinea (PNG). Often, learning technologies are adopted without careful consideration of the users’ requirements, especially their cultural influences, which sometimes hinder the effective implementation of chosen technologies for learning. This article discusses the key findings related to technology limitations, cultural influences, communication issues, and other challenges unique to PNG. It highlights that students and lecturers are keen to embrace technology in teaching and learning; however, institutional constraints hinder the successful implementation of technology that would allow them to advance learning. This, coupled with cultural influences such as traditional customs, practices, and belief systems, also affects how Western education is delivered. The article concludes with recommendations for implementing culturally sensitive learning management systems that can accommodate infrastructure and social challenges. | I20: Yalamu et al. | J20: 18 | M20: 85 | N20: 99 | O20: 15 | Q20: 10.1109/TLT.2024.3514832 | R20: https://ieeexplore.ieee.org/document/10806484/ | T20: Article | U20: https://ieeexplore.ieee.org/document/10806484/ | V20: IEEE Transactions on Learning Technologies | W20: 1939-1382
A21: Jiang, Tiantian (57887363700) | B21: 57887363700 | C21: Inconforme - Não está conforme o tema | D21: Inconforme - Não está conforme o tema | F21: Language Application in Social Networking Activities Based on Embedded Computing | G21: 2023 | H21: This paper investigates the application analysis of language in social network activities based on embedded computing. First, this paper points out the challenges posed by the massive amount of user-generated content in social networks, and explores the potential of embedded computing in the analysis of language applications. Then this paper describes the research method, compares the data mining algorithm and the machine learning algorithm, and tests the accuracy and recall rate of the two algorithms and surveys the satisfaction degree. Finally, this paper presents the results of an experimental evaluation of the effectiveness of embedded computing-based approaches on the task of language application analysis in social network activity. The experimental results show that the two algorithms have achieved good performance in accuracy and recall, and can quickly respond to user needs and protect user privacy, and the accuracy rate of the data mining algorithm is 76%-84%. Linguistic application analysis in social network activities based on embedded computing has broad application prospects, which can provide users with personalized experience and valuable information insights. | I21: Ying Yang; Rui Ma | M21: 126 | N21: 131 | O21: 6 | Q21: 10.1109/CSMIS60634.2023.00029 | R21: https://ieeexplore.ieee.org/document/10549075/ | T21: Conference Paper | U21: https://ieeexplore.ieee.org/document/10549075/ | V21: 2023 International Conference on Computer Simulation and Modeling, Information Security (CSMIS)
A22: Kaeppel, Kristi (57213669244) | B22: 57213669244 | C22: Inconforme - Não está conforme o tema | D22: Inconforme - Não está conforme o tema | F22: Leveraging AI to Personalize HR Marketing Campaigns: A Data-Driven Approach | G22: 2025 | H22: The research proposes an AI-driven personalization framework for enhancing the efficiency and engagement of HR marketing campaigns. The system integrates real-time data processing, collaborative filtering, and feedback loops to dynamically recommend job opportunities tailored to individual candidate preferences. Using an HR-related dataset from Kaggle, the framework preprocesses data by handling missing values, scaling numerical features via Min-Max Scaling, and reducing dimensionality using Principal Component Analysis (PCA). Collaborative Filtering is employed to predict candidate preferences through matrix factorization, dynamically updating recommendations based on real-time user interactions. The experimental evaluation highlights the framework's superior performance compared to traditional methods. Click-Through Rate (CTR) improved significantly, with AI-driven personalization achieving 30% compared to 18% from rule-based methods and 12% from the baseline. Accuracy analysis revealed that Collaborative Filtering outperformed random and content-based methods, achieving the highest precision (85%), recall (88%), and F1-score (86%). These results underscore the effectiveness of AI in aligning candidate preferences with recruitment goals while ensuring dynamic adaptation through feedback. The proposed system also seamlessly integrates personalized insights into HR marketing channels such as job portals, email campaigns, and social media advertisements, optimizing recruitment processes and enhancing user engagement. Future research aims to extend the dataset to include diverse candidate profiles, incorporate multi-modal data sources, and leverage deep learning for improved recommendation accuracy. Additionally, explainability techniques will be explored to ensure transparency and build trust among users. This framework demonstrates the transformative potential of AI-driven personalization in reshaping HR marketing strategies. | I22: Moath Mahmoud Alshar; Ameet Sao; Manish Sharma; Sunil Kadyan; Vuda Sreenivasa Rao; B. Anitha Vijayalakshmi | M22: 225 | N22: 230 | O22: 5 | Q22: 10.1109/ISACC65211.2025.10969174 | R22: https://doi.org/10.1109/ISACC65211.2025.10969174 | T22: Conferência | U22: https://ieeexplore.ieee.org/document/10969174/ | W22: 979-8-3315-2389-3
A23: Bhedasgaonkar, R.C. (55853789300); Chavan, M.S. (11340206600); Kubade, P.R. (56695270600); Patil, S.B. (58276873800) | B23: 55853789300; 11340206600; 56695270600; 58276873800 | C23: Inconforme - Não está conforme o tema | D23: Inconforme - Não está conforme o tema | F23: Leveraging Cloud Technology for Enhanced Online Examination System | G23: 2024 | H23: An online cloud-based Examination Framework is a web application in which the user can try an online exam. Through a web browser, the user can search for an exam for a particular subject that they want to improve. Users can also review their earlier exams and learn and improve their mistakes. The user can login using his/her account details of interest, or modern users can set up an account exceptionally rapidly using the enrollment strategy. They ought to grant the subtle elements of their title, contact and their level of education. | I23: Shrimal et al. | M23: 1 | N23: 5 | O23: 5 | Q23: 10.1109/ICTBIG64922.2024.10911607 | R23: https://ieeexplore.ieee.org/document/10911607/ | T23: Conference Paper | U23: https://ieeexplore.ieee.org/document/10911607/ | V23: 2024 IEEE 4th International Conference on ICT in Business Industry & Government (ICTBIG)
A24: Günay, Cengiz (57207555780); Doloc-Mihu, Anca (8529451500); Barakat, Rahaf (57190948922); Gluick, Thomas (6603391170); Moore, Catherine A. (57219715456) | B24: 57207555780; 8529451500; 57190948922; 6603391170; 57219715456 | C24: Inconforme - Não está conforme o tema | D24: Inconforme - Não está conforme o tema | F24: Long-term Impacts of K–12 AI Education Interventions on Social Media Mechanisms | G24: 2026 | H24: This full research paper presents a delayed posttest study on the effects of classroom activities and educational technologies in the context of engineering education, specifically AI education, using social media algorithms as a context. School projects were carried out with 12 regular classes of Finnish 5th and 8th grade students, using two newly developed educational apps designed for classroom use. Data were collected through a pre-test, post-test, and a delayed post-test administered six months after the intervention. This study investigated whether, and to what extent, did the conceptual improvements found immediately after the intervention persist. A logistic mixed model analysis of students’ (N=142) responses in delayed post-test indicated an improved understanding of social media mechanisms compared to the pre-test, but a slight overall decrease compared to the post-test. The results suggest that children can gradually develop more sophisticated and scientifically grounded understandings of the opaque, data-driven systems they encounter in everyday life, but this requires systematic scaffolding and cumulative learning trajectories. | I24: Henriikka Vartiainen; Juho Kahila; Nicolas Pope; Sonsoles López-Pernas; Teemu Valtonen; Matti Tedre | O24: 9 | Q24: 101109 | R24: https://ieeexplore.ieee.org/document/11328565
A25: Yang, Chunye (57223631981) | B25: 57223631981 | C25: Inconforme - Não está conforme o tema | D25: Inconforme - Não está conforme o tema | F25: Maximizing the Potential of Artificial Intelligence in Digital Marketing | G25: 2023 | H25: The use of artificial intelligence (AI) in digital marketing has become increasingly prevalent in recent years, with businesses seeking to maximize the potential of this technology to improve customer engagement and drive sales. However, despite the promise of AI, many organizations struggle to fully leverage its capabilities in their digital marketing efforts. This study aims to address this gap by exploring how businesses can maximize the potential of AI in digital marketing. Through a comprehensive review of the literature and empirical research, the authors identify the key challenges and opportunities associated with the use of AI in digital marketing and provide practical recommendations for businesses seeking to optimize their AI strategies. The study highlights the potential benefits of using AI in digital marketing, including the ability to personalize customer experiences, optimize advertising campaigns, and improve customer engagement. However, several challenges are associated with the use of AI, such as data privacy concerns and the potential for bias in algorithms. To address these challenges, the study provides practical recommendations for businesses seeking to maximize the potential of AI in their digital marketing efforts. These include developing a clear AI strategy, investing in high-quality data, and ensuring that AI models are transparent and explainable. Overall, this manuscript provides a valuable contribution to the field of digital marketing by demonstrating how businesses can leverage the power of AI to improve customer engagement and drive sales. By following the practical recommendations outlined in this study, businesses can position themselves for success in the rapidly evolving world of digital marketing. | I25: Pramod Kumar; Parveen Kumar Tomar; Shikha Bharti; Suman Naredla; Read Khalid Ibrahim; Malik Bader Alazzam | M25: 2736 | N25: 2741 | O25: 5 | P25: 11 | Q25: 10.1109/ICACITE57410.2023.10183113. | S25: https://ieeexplore.ieee.org/document/10183113 | T25: conferencia | U25: aberto | V25: International Conference on Advance Computing and Innovative Technologies in Engineering (ICACITE)
A26: Dai, Yin (57218701565) | B26: 57218701565 | C26: Inconforme - Não está conforme o tema | D26: Inconforme - Não está conforme o tema | F26: Opportunities and Challenges in Data-Centric AI | G26: 2024 | H26: Artificial intelligence (AI) systems are trained to solve complex problems and learn to perform specific tasks by using large volumes of data, such as prediction, classification, recognition, decision-making, etc. In the past three decades, AI research has focused mostly on the model-centric approach compared to the data-centric approach. In the model-centric approach, the focus is to improve the code or model architecture to enhance performance, whereas in data-centric AI, the focus is to improve the dataset to enhance performance. Data is food for AI. As a result, there has been a recent push in the AI community toward data-centric AI from model-centric AI. This paper provides a comprehensive and critical analysis of the current state of research in data-centric AI, presenting insights into the latest developments in this rapidly evolving field. By emphasizing the importance of data in AI, the paper identifies the key challenges and opportunities that must be addressed to improve the effectiveness of AI systems. Finally, this paper gives some recommendations for research opportunities in data-centric AI. | I26: Kumar et. al. | J26: 12 | M26: 33173 | N26: 33189 | O26: 16 | Q26: 10.1109/ACCESS.2024.3369417 | R26: https://ieeexplore.ieee.org/document/10444552/ | T26: Conference paper | U26: https://ieeexplore.ieee.org/document/10444552/ | V26: IEEE Access | W26: 2169-3536
A27: Osmani, Mohamad (56818858000); Hindi, Nitham M. (6507760633); Weerakkody, Vishanth (16029961500) | B27: 56818858000; 6507760633; 16029961500 | C27: Inconforme - Não está conforme o tema | D27: Inconforme - Não está conforme o tema | F27: MMInfluencer: A Multimodal AI Framework for Influencer Marketing Tasks Using Large Language Models | G27: 2026 | H27: Influencer marketing involves brands partnering with influencers to promote products, often through combined text and image posts on social media platforms. This multimodal data is critical for identifying suitable products for effective marketing practice. In this study, we presented MMInfluencer, a novel framework that addressed the critical upstream challenge of knowledge extraction from unstructured multimodal social media data. Our framework operationalized communication theories, the heuristic-systematic model (HSM) and dual coding theory (DCT), to guide large language models (LLMs) in constructing a high-quality knowledge graph (KG) from the multimodal posts and biographies of 1000 Instagram influencers. Human assessment of the KG confirmed its relevance and completeness with accuracy scores of 0.89 and 0.75, respectively. We then examined the KG’s efficacy in various influencer marketing tasks using graph-based learning methods and retrieval-augmented generation (RAG) technology. The KG derived from multimodal data significantly improved product category prediction and recommendation tasks, with the Node2Vec model showing improvements of 20.47% (AUROC, p < 0.0001) and 1142.15% (NDCG@20, p < 0.0001), respectively. In contrast, the RAG method was ineffective, yielding an accuracy of just 0.1195 (\pm 0.0162). Furthermore, the LLM-extracted KG significantly improved performance in challenging scenarios, where the best model achieved improvements of 155.51% (NDCG@20, p = 0.0170) for emerging influencers (zero-shot) and 1144.51% (NDCG@20, p < 0.0001) for influencers with scarce data (cold-start). Our research underscores the potential of leveraging multimodal data, LLMs, and graph-based learning methods for effective influencer marketing. | I27: Jiannan Yang; Duorong Wang; Lei Zhu; Houmin Yan; Qingpeng Zhang | J27: 13 | M27: 321 | N27: 332 | O27: 11 | Q27: 10.1109/TCSS.2025.3597544 | R27: https://doi.org/10.1109/TCSS.2025.3597544 | T27: Artigo de períodico | U27: https://ieeexplore.ieee.org/document/11151670/ | W27: 2329-924X
A28: Chan, Cecilia Ka Yuk (55086149300); Lee, Katherine K. W. (57208229343) | B28: 55086149300; 57208229343 | C28: Inconforme - Não está conforme o tema | D28: Inconforme - Não está conforme o tema | F28: Opportunities and Challenges in Data-Centric AI | G28: 2024 | H28: Artificial intelligence (AI) systems are trained to solve complex problems and learn to perform specific tasks by using large volumes of data, such as prediction, classification, recognition, decision-making, etc. In the past three decades, AI research has focused mostly on the model-centric approach compared to the data-centric approach. In the model-centric approach, the focus is to improve the code or model architecture to enhance performance, whereas in data-centric AI, the focus is to improve the dataset to enhance performance. Data is food for AI. As a result, there has been a recent push in the AI community toward data-centric AI from model-centric AI. This paper provides a comprehensive and critical analysis of the current state of research in data-centric AI, presenting insights into the latest developments in this rapidly evolving field. By emphasizing the importance of data in AI, the paper identifies the key challenges and opportunities that must be addressed to improve the effectiveness of AI systems. Finally, this paper gives some recommendations for research opportunities in data-centric AI. | I28: SUSHANT KUMAR, SUMIT DATTA , VISHAKHA SINGH, (Member, IEEE), SANJAY KUMAR SINGH, AND RITESH SHARMA | J28: 12 | M28: 33173 | N28: 33189 | O28: 17 | Q28: 101109 | R28: https://ieeexplore.ieee.org/document/10444552//
